<?xml version="1.0" ?>
<!-- =================================================================================== -->
<!-- |    This document was autogenerated by xacro from ./door.xml.xacro          | -->
<!-- |    EDITING THIS FILE BY HAND IS NOT RECOMMENDED                                 | -->
<!-- =================================================================================== -->
<mujoco model="door">
  <asset>
    <material name="mat_frame" rgba="0.5 0.5 0.5 0.4"/>
    <material name="mat_panel" rgba="1.0 1.0 1.0 1.0"/>
    <material name="mat_handle" rgba="0.0 0.0 0.0 1.0"/>
  </asset>
  <worldbody>
    <body name="door_frame" pos="-0.85 -0.435 0.955" quat="0.70710678 0.0 0.0 0.70710678" user="1001 0 2002 -0.4 -0.1 0.252 0 0.3 0.5">
      <geom material="mat_frame" pos="-0.4 0 0" size="0.4 0.02 0.955" type="box"/>
      <geom material="mat_frame" pos="1.27 0 0" size="0.4 0.02 0.955" type="box"/>
      <site group="3" name="S_handle_target" pos="0.75 -0.5 -0.18" size="0.02"/>
      <body name="door_panel" pos="0.435 0 0">
        <inertial diaginertia="0.4173 0.5667 0.1507" mass="10.0" pos="0 0 0" quat="1 0 0 0"/>
        <geom friction="0.5 0.1 0.001" material="mat_panel" size="0.435 0.02 0.95" type="box"/>
        <joint axis="0 0 1" damping="5.0" frictionloss="5.0" limited="true" name="door_hinge" pos="0.435 0 0" range="-1.57 1.57" springref="0.0" stiffness="30.0"/>
        <body name="door_latch" pos="-0.375 0 0.0">
          <inertial diaginertia="0.0483771 0.0410001 0.0211013" mass="0.353743" pos="-0.027762 0.0238544 0.0" quat="0.365653 0.605347 -0.36522 0.605365"/>
          <joint axis="0 1 0" damping="1.0" frictionloss="0.2" name="door_latch" pos="0 0 0" range="0.0 1.6" springref="0.0" stiffness="2.0"/>
          <geom material="mat_handle" quat="0.7071068 0.7071068 0 0" size="0.01 0.075" type="cylinder"/>
          <geom condim="4" material="mat_handle" pos="0.0625 -0.075 0" quat="0.7071068 0 0.7071068 0" size="0.01 0.0625" type="capsule"/>
          <geom material="mat_handle" pos="0.0 0.0425 0" quat="0.7071068 0 0.7071068 0" size="0.02 0.055" type="capsule"/>
          <site group="3" name="S_handle" pos="0.15 -0.15 0.0" size="0.02"/>
        </body>
      </body>
    </body>
  </worldbody>
  <contact>
    <exclude body1="door_frame" body2="door_panel"/>
  </contact>
</mujoco>
